---
title: 例外と例外処理 - C# プログラミング ガイド
description: 例外と例外処理について説明します。 これらの C# 機能は、プログラムの実行中に発生する予期しない状況や例外的な状況に対処するのに役立ちます。
ms.date: 12/09/2020
helpviewer_keywords:
- exception handling [C#]
- exceptions [C#]
- C# language, exceptions
ms.assetid: 0001887f-4fa2-47e2-8034-2819477e2344
ms.openlocfilehash: 245299707254c7bafb4589ee8031a107921ca2a7
ms.sourcegitcommit: e7e0921d0a10f85e9cb12f8b87cc1639a6c8d3fe
ms.translationtype: HT
ms.contentlocale: ja-JP
ms.lasthandoff: 04/09/2021
ms.locfileid: "107255403"
---
# <a name="exceptions-and-exception-handling-c-programming-guide"></a><span data-ttu-id="f286b-104">例外と例外処理 (C# プログラミング ガイド)</span><span class="sxs-lookup"><span data-stu-id="f286b-104">Exceptions and Exception Handling (C# Programming Guide)</span></span>

<span data-ttu-id="f286b-105">C# 言語の例外処理機能は、プログラムの実行時に発生する予期しない状況や例外的な状況を扱うのに役立ちます。</span><span class="sxs-lookup"><span data-stu-id="f286b-105">The C# language's exception handling features help you deal with any unexpected or exceptional situations that occur when a program is running.</span></span> <span data-ttu-id="f286b-106">例外処理では、キーワード `try`、`catch`、および `finally` を使用して、成功しない可能性があるアクションを試行し、適切な場合はエラーを処理して、後からリソースをクリーンアップします。</span><span class="sxs-lookup"><span data-stu-id="f286b-106">Exception handling uses the `try`, `catch`, and `finally` keywords to try actions that may not succeed, to handle failures when you decide that it's reasonable to do so, and to clean up resources afterward.</span></span> <span data-ttu-id="f286b-107">例外の発生元は、共通言語ランタイム (CLR)、.NET、サード パーティ ライブラリ、またはアプリケーション コードなどさまざまです。</span><span class="sxs-lookup"><span data-stu-id="f286b-107">Exceptions can be generated by the common language runtime (CLR), by .NET or third-party libraries, or by application code.</span></span> <span data-ttu-id="f286b-108">例外は、`throw` キーワードを使用して作成されます。</span><span class="sxs-lookup"><span data-stu-id="f286b-108">Exceptions are created by using the `throw` keyword.</span></span>

<span data-ttu-id="f286b-109">コードが直接呼び出したメソッドではなく、呼び出し履歴の下の方にある別のメソッドによって例外がスローされることも多くあります。</span><span class="sxs-lookup"><span data-stu-id="f286b-109">In many cases, an exception may be thrown not by a method that your code has called directly, but by another method further down in the call stack.</span></span> <span data-ttu-id="f286b-110">例外がスローされた場合、CLR によってスタックがアンワインドされ、`catch` ブロックを持つメソッドで特定の例外の種類がないかを調べ、もしあれば最初に見つかった `catch` ブロックを実行します。</span><span class="sxs-lookup"><span data-stu-id="f286b-110">When an exception is thrown, the CLR will unwind the stack, looking for a method with a `catch` block for the specific exception type, and it will execute the first such `catch` block that if finds.</span></span> <span data-ttu-id="f286b-111">適切な `catch` ブロックが呼び出し履歴にない場合は、プロセスが終了し、ユーザーにメッセージが表示されます。</span><span class="sxs-lookup"><span data-stu-id="f286b-111">If it finds no appropriate `catch` block anywhere in the call stack, it will terminate the process and display a message to the user.</span></span>

<span data-ttu-id="f286b-112">この例では、メソッドが 0 による除算をテストしてエラーをキャッチします。</span><span class="sxs-lookup"><span data-stu-id="f286b-112">In this example, a method tests for division by zero and catches the error.</span></span> <span data-ttu-id="f286b-113">例外処理せずにプログラムは終了し、"**DivideByZeroException はハンドルされませんでした。** " というエラーが表示されます。</span><span class="sxs-lookup"><span data-stu-id="f286b-113">Without the exception handling, this program would terminate with a **DivideByZeroException was unhandled** error.</span></span>

:::code language="csharp" source="snippets/exceptions/ExceptionTest.cs" ID="ExceptionTest":::

## <a name="exceptions-overview"></a><span data-ttu-id="f286b-114">例外の概要</span><span class="sxs-lookup"><span data-stu-id="f286b-114">Exceptions Overview</span></span>

<span data-ttu-id="f286b-115">例外には、次の特徴があります。</span><span class="sxs-lookup"><span data-stu-id="f286b-115">Exceptions have the following properties:</span></span>

- <span data-ttu-id="f286b-116">例外はすべて最終的に `System.Exception` から派生した種類になります。</span><span class="sxs-lookup"><span data-stu-id="f286b-116">Exceptions are types that all ultimately derive from `System.Exception`.</span></span>
- <span data-ttu-id="f286b-117">例外をスローする可能性のあるステートメントの周囲で `try` ブロックを使用します。</span><span class="sxs-lookup"><span data-stu-id="f286b-117">Use a `try` block around the statements that might throw exceptions.</span></span>
- <span data-ttu-id="f286b-118">`try` ブロックで例外が発生すると、コントロールのフローが、呼び出し履歴内の関連付けられている最初の例外ハンドラーにジャンプします。</span><span class="sxs-lookup"><span data-stu-id="f286b-118">Once an exception occurs in the `try` block, the flow of control jumps to the first associated exception handler that is present anywhere in the call stack.</span></span> <span data-ttu-id="f286b-119">C# では、`catch` キーワードは例外ハンドラーの定義に使用されます。</span><span class="sxs-lookup"><span data-stu-id="f286b-119">In C#, the `catch` keyword is used to define an exception handler.</span></span>
- <span data-ttu-id="f286b-120">特定の例外の例外ハンドラーが存在しない場合、プログラムは実行を停止し、エラー メッセージを表示します。</span><span class="sxs-lookup"><span data-stu-id="f286b-120">If no exception handler for a given exception is present, the program stops executing with an error message.</span></span>
- <span data-ttu-id="f286b-121">処理できない例外はキャッチしないようにして、アプリケーションを既知の状態に保ちます。</span><span class="sxs-lookup"><span data-stu-id="f286b-121">Don't catch an exception unless you can handle it and leave the application in a known state.</span></span> <span data-ttu-id="f286b-122">`System.Exception` をキャッチした場合は、`catch` ブロックの最後で `throw` キーワードを使用して、それを再スローします。</span><span class="sxs-lookup"><span data-stu-id="f286b-122">If you catch `System.Exception`, rethrow it using the `throw` keyword at the end of the `catch` block.</span></span>
- <span data-ttu-id="f286b-123">`catch` ブロックで例外変数を定義した場合、それを使用して、発生した例外の種類に関する詳細を入手することができます。</span><span class="sxs-lookup"><span data-stu-id="f286b-123">If a `catch` block defines an exception variable, you can use it to obtain more information about the type of exception that occurred.</span></span>
- <span data-ttu-id="f286b-124">例外は、`throw` キーワードを使用してプログラムで明示的に生成することができます。</span><span class="sxs-lookup"><span data-stu-id="f286b-124">Exceptions can be explicitly generated by a program by using the `throw` keyword.</span></span>
- <span data-ttu-id="f286b-125">例外オブジェクトには、呼び出し履歴の状態やエラーの説明など、エラーに関する詳細情報が含まれています。</span><span class="sxs-lookup"><span data-stu-id="f286b-125">Exception objects contain detailed information about the error, such as the state of the call stack and a text description of the error.</span></span>
- <span data-ttu-id="f286b-126">`finally` ブロック内のコードは、例外がスローされた場合でも実行されます。</span><span class="sxs-lookup"><span data-stu-id="f286b-126">Code in a `finally` block is executed even if an exception is thrown.</span></span> <span data-ttu-id="f286b-127">`finally` ブロックを使用してリソースを解放します。たとえば、`try` ブロックで開かれたストリームまたはファイルを閉じます。</span><span class="sxs-lookup"><span data-stu-id="f286b-127">Use a `finally` block to release resources, for example to close any streams or files that were opened in the `try` block.</span></span>
- <span data-ttu-id="f286b-128">.NET のマネージド例外は、Win32 構造化例外処理メカニズムの上に実装されます。</span><span class="sxs-lookup"><span data-stu-id="f286b-128">Managed exceptions in .NET are implemented on top of the Win32 structured exception handling mechanism.</span></span> <span data-ttu-id="f286b-129">詳細については、「[構造化例外処理 (C/C++)](/cpp/cpp/structured-exception-handling-c-cpp)」と「[A Crash Course on the Depths of Win32 Structured Exception Handling (Win32 構造化例外処理に関する短期集中コース)」](http://bytepointer.com/resources/pietrek_crash_course_depths_of_win32_seh.htm)を参照してください。</span><span class="sxs-lookup"><span data-stu-id="f286b-129">For more information, see [Structured Exception Handling (C/C++)](/cpp/cpp/structured-exception-handling-c-cpp) and [A Crash Course on the Depths of Win32 Structured Exception Handling](http://bytepointer.com/resources/pietrek_crash_course_depths_of_win32_seh.htm).</span></span>

## <a name="c-language-specification"></a><span data-ttu-id="f286b-130">C# 言語仕様</span><span class="sxs-lookup"><span data-stu-id="f286b-130">C# Language Specification</span></span>

<span data-ttu-id="f286b-131">詳細については、「[C# 言語の仕様](/dotnet/csharp/language-reference/language-specification/introduction)」の「[例外](~/_csharplang/spec/exceptions.md)」を参照してください。</span><span class="sxs-lookup"><span data-stu-id="f286b-131">For more information, see [Exceptions](~/_csharplang/spec/exceptions.md) in the [C# Language Specification](/dotnet/csharp/language-reference/language-specification/introduction).</span></span> <span data-ttu-id="f286b-132">言語仕様は、C# の構文と使用法に関する信頼性のある情報源です。</span><span class="sxs-lookup"><span data-stu-id="f286b-132">The language specification is the definitive source for C# syntax and usage.</span></span>

## <a name="see-also"></a><span data-ttu-id="f286b-133">関連項目</span><span class="sxs-lookup"><span data-stu-id="f286b-133">See also</span></span>

- <xref:System.SystemException>
- [<span data-ttu-id="f286b-134">C# のキーワード</span><span class="sxs-lookup"><span data-stu-id="f286b-134">C# Keywords</span></span>](../../language-reference/keywords/index.md)
- [<span data-ttu-id="f286b-135">throw</span><span class="sxs-lookup"><span data-stu-id="f286b-135">throw</span></span>](../../language-reference/keywords/throw.md)
- [<span data-ttu-id="f286b-136">try-catch</span><span class="sxs-lookup"><span data-stu-id="f286b-136">try-catch</span></span>](../../language-reference/keywords/try-catch.md)
- [<span data-ttu-id="f286b-137">try-finally</span><span class="sxs-lookup"><span data-stu-id="f286b-137">try-finally</span></span>](../../language-reference/keywords/try-finally.md)
- [<span data-ttu-id="f286b-138">try-catch-finally</span><span class="sxs-lookup"><span data-stu-id="f286b-138">try-catch-finally</span></span>](../../language-reference/keywords/try-catch-finally.md)
- [<span data-ttu-id="f286b-139">例外</span><span class="sxs-lookup"><span data-stu-id="f286b-139">Exceptions</span></span>](../../../standard/exceptions/index.md)
